<?xml version="1.0"?>
<robot name="softlegisaac">
<link name="world">
</link>
  <joint name="rootJoint" type="fixed">
    <origin xyz="0. 0. 0." rpy="0. 0. 0."/>
    <parent link="world"/>
    <child link="softleg_1_cart_link"/>
  </joint>
  <joint name="softleg_1_cart_joint" type="prismatic">
    <origin xyz="0. -0.01 0.0 " rpy="3.1415927 -1.5707963 0. "/>
    <parent link="softleg_1_cart_link"/>
    <child link="softleg_1_base_link"/>
    <axis xyz="1 0 0"/>
    <limit lower="0" upper="3" effort="1000" velocity="80"/>
  </joint>
  <joint name="softleg_1_hip_joint" type="revolute">
    <origin xyz="0. -0.255 0.07 " rpy="0. -1.5707963 0. "/>
    <parent link="softleg_1_base_link"/>
    <child link="softleg_1_thigh_link"/>
    <axis xyz="1 0 0"/>
    <limit lower="-3.1415927" upper="3.1415927" effort="5000." velocity="57.6059555"/>
  </joint>
  <joint name="softleg_1_knee_joint" type="revolute">
    <origin xyz="0.0275 -0.175 0. " rpy="1.5707964 0. 0. "/>
    <parent link="softleg_1_thigh_link"/>
    <child link="softleg_1_calf_link"/>
    <axis xyz="1 0 0"/>
    <limit lower="-3.1415927" upper="3.1415927" effort="5000." velocity="57.6059555"/>
  </joint>
  <link name="softleg_1_base_link">
    <inertial>
      <origin xyz="0. 0. 0." rpy="0. 0. 0."/>
      <mass value="0.9724552"/>
      <inertia ixx="0.0016984399" ixy="-0.00098390475" ixz="-0.0013053791" iyy="0.020148637999999996" iyz="0.00015383174" izz="0.019764512999999997"/>
      <!-- <inertia ixx="0." ixy="0." ixz="0." iyy="0." iyz="0." izz="0."/> -->
    </inertial>
    <visual>
      <origin xyz="0. 0. 0." rpy="0. 0. -1.5707964"/>
      <geometry>
        <mesh filename="/home/michele/jumpsim_exp_ws/src/softleg_description/meshes/softleg_1_base_link_visuals_mesh_0.obj" scale="0.001 0.001 0.001"/>
      </geometry>
    </visual>
    <collision>
      <origin xyz="-0.0004043 -0.256 0.04 " rpy="0. 0. -1.5707964"/>
      <geometry>
        <cylinder radius="0.035" length="0.025"/>
      </geometry>
    </collision>
  </link>
  <link name="softleg_1_calf_link">
    <inertial>
      <origin xyz="0. 0. 0." rpy="0. 0. 0."/>
      <mass value="0.0762175"/>
      <inertia ixx="6.0006428999999995e-05" ixy="-0.011984835" ixz="3.6890095e-10" iyy="0.00047243319" iyz="1.2686112999999998e-10" izz="0.0005204986699999999"/>
      <!-- <inertia ixx="0." ixy="0." ixz="0." iyy="0." iyz="0." izz="0."/> -->
    </inertial>
    <visual>
      <origin xyz="-0. 0. -0." rpy="0. -1.5707963 0. "/>
      <geometry>
        <mesh filename="/home/michele/jumpsim_exp_ws/src/softleg_description/meshes/softleg_1_calf_link_visuals_mesh_0.obj" scale="0.001 0.001 0.001"/>
      </geometry>
    </visual>
    <collision>
      <origin xyz="0.018 0. 0.175" rpy="0. -1.5707963 0. "/>
      <geometry>
        <cylinder radius="0.015" length="0.01"/>
      </geometry>
    </collision>
  </link>
  <link name="softleg_1_cart_link">
    <inertial>
      <origin xyz="0. 0. 0." rpy="0. 0. 0."/>
      <mass value="0.00001"/>
      <inertia ixx="1.0000000000000001e-11" ixy="0.0" ixz="0.0" iyy="0.0" iyz="0.0" izz="0.0"/>
      <!-- <inertia ixx="0." ixy="0." ixz="0." iyy="0." iyz="0." izz="0."/> -->
    </inertial>
    <visual>
      <origin xyz="0. 0. 0." rpy="0. 0. -3.1415925"/>
      <geometry>
        <mesh filename="/home/michele/jumpsim_exp_ws/src/softleg_description/meshes/softleg_1_cart_link_visuals_mesh_0.obj" scale="0.001 0.001 0.001"/>
      </geometry>
    </visual>
  </link>
  <link name="softleg_1_thigh_link">
    <inertial>
      <origin xyz="0. 0. 0." rpy="0. 0. 0."/>
      <mass value="0.435789"/>
      <inertia ixx="0." ixy="0." ixz="0." iyy="0." iyz="0." izz="0."/>
    </inertial>
    <visual>
      <origin xyz="0. -0.073 0. " rpy="0. 0. -1.5707964"/>
      <geometry>
        <mesh filename="/home/michele/jumpsim_exp_ws/src/softleg_description/meshes/softleg_1_thigh_link_visuals_mesh_0.obj" scale="0.001 0.001 0.001"/>
      </geometry>
    </visual>
    <collision>
      <origin xyz="0.0125 -0.1840615 0. " rpy="1.5707964 0. -1.5707964"/>
      <geometry>
        <cylinder radius="0.03" length="0.027"/>
      </geometry>
    </collision>
  </link>
  <!-- <link name="softleg_cart">
    <visual>
      <origin xyz="0. 0. 1." rpy="0. 0. 0."/>
      <geometry>
        <sphere radius="0.05"/>
      </geometry>
    </visual>
  </link> -->

  <!-- <gazebo> -->
  <gazebo reference="world">
      <material>Gazebo/White</material>
  </gazebo>
  <gazebo>
    <plugin filename="libgazebo_ros2_control.so" name="gazebo_ros2_control">
        <parameters>/home/michele/jumpsim_exp_ws/src/softleg_gazebo/config/softleg_gazebo_sim_jnt_PD.yaml</parameters>
    </plugin>
  </gazebo>
  <ros2_control name="GazeboSystem" type="system">
        <hardware>
            <plugin>gazebo_ros2_control/GazeboSystem</plugin>
        </hardware>
      <joint name="softleg_1_cart_joint">
                <command_interface name="effort" />
                <state_interface name="position">
                    <param name="initial_value">-0.0</param>
                </state_interface>
                <state_interface name="velocity">
                    <param name="initial_value">0.0</param>
                </state_interface>
                <state_interface name="effort" />
      </joint>    
      <joint name="softleg_1_hip_joint">
              <command_interface name="effort" />
              <state_interface name="position">
                  <param name="initial_value">-0.0</param>
              </state_interface>
              <state_interface name="velocity">
                  <param name="initial_value">0.0</param>
              </state_interface>
              <state_interface name="effort" />
      </joint>
      <joint name="softleg_1_knee_joint">
                <command_interface name="effort" />
                <state_interface name="position">
                    <param name="initial_value">-0.0</param>
                </state_interface>
                <state_interface name="velocity">
                    <param name="initial_value">0.0</param>
                </state_interface>
                <state_interface name="effort" />
            </joint>
        </ros2_control>
        <gazebo reference="softleg_1_cart_link">
            <gravity>true</gravity>
            <material>Gazebo/Grey</material>
            <!-- <kp>1e15</kp>
            <kd>1e15</kd>
            <mu1>1</mu1>
            <mu2>1</mu2>
            <slip1>0</slip1>
            <slip2>0</slip2>
            <mu1>0.8</mu1>
            <mu2>0.8</mu2>
            <collision>
              <surface>
                <contact>
                  <ode>
                    <min_depth>0.01</min_depth>
                    <max_vel>0.1</max_vel>
                  </ode>
                </contact>
              </surface>
            </collision> -->
          </gazebo>
          <gazebo reference="softleg_1_base_link">
          <gravity>true</gravity>
          <material>Gazebo/Grey</material>
          <!-- <kp>1e15</kp>
          <kd>1e15</kd>
          <mu1>0.8</mu1>
          <mu2>0.8</mu2>
          <slip1>0</slip1>
          <slip2>0</slip2>
          <collision>
            <surface>
              <contact>
                <ode>
                  <min_depth>0.01</min_depth>
                  <max_vel>0.1</max_vel>
                </ode>
              </contact>
            </surface>
          </collision> -->
        </gazebo>
        <gazebo reference="softleg_1_thigh_link">
          <gravity>true</gravity>
          <material>Gazebo/Grey</material>
          <!-- <kp>1e15</kp>
          <kd>1e15</kd>
          <mu1>0.8</mu1>
          <mu2>0.8</mu2>
          <collision>
            <surface>
              <contact>
                <ode>
                  <min_depth>0.01</min_depth>
                  <max_vel>0.1</max_vel>
                </ode>
              </contact>
            </surface>
          </collision> -->
        </gazebo>
        <gazebo reference="softleg_1_calf_link">
          <gravity>true</gravity>
          <material>Gazebo/Grey</material>
          <!-- <kp>1e15</kp>
          <kd>1e15</kd>
          <mu1>0.8</mu1>
          <mu2>0.8</mu2>
          <collision>
            <surface>
              <contact>
                <ode>
                  <min_depth>0.01</min_depth>
                  <max_vel>0.1</max_vel>
                </ode>
              </contact>
            </surface>
          </collision> -->
        </gazebo> 
</robot>
