<mujoco model="leg_constrained">
  <compiler angle="radian"/>
  <option actuatorgroupdisable="0 1 2 3 4 5">
    <flag constraint="disable" eulerdamp="disable" override="enable" energy="enable" fwdinv="enable" invdiscrete="enable" multiccd="enable" island="enable"/>
  </option>
  <worldbody>
    <geom size="0.1345 0.0285 0.03" pos="0.025 0.1445 0.5" quat="2.31079e-07 -0.707107 0.707107 2.31079e-07" type="box" rgba="1 1 1 1"/>
    <body name="LH_UPPER_LEG" pos="-0.0189999 0.24 0.5" quat="2.31079e-07 -0.707107 0.707107 2.31079e-07">
      <inertial pos="-0.0724874 0.0315826 0.00248124" quat="0.546772 0.454856 0.541001 0.448848" mass="0.476697" diaginertia="0.00306152 0.00305004 0.000215348"/>
      <joint name="LH_HFE" pos="0 0 0" axis="0 1 0" range="-3.14159 3.14159" actuatorfrcrange="-5 5"/>
      <geom size="0.1345 0.0285 0.03" pos="-0.0945 0.015 0" type="box" rgba="1 1 1 1"/>
      <body name="LH_LOWER_LEG" pos="-0.19 0.044 0">
        <inertial pos="-0.0660893 0.0198901 1.55259e-05" quat="0.487419 0.486067 0.513613 0.512215" mass="0.046942" diaginertia="0.000213 0.000211548 4.57013e-06"/>
        <joint name="LH_KFE" pos="0 0 0" axis="0 1 0" range="-3.14159 3.14159" actuatorfrcrange="-5 5"/>
      </body>
    </body>
  </worldbody>
</mujoco>
