<?xml version="1.0" ?>
<!-- =================================================================================== -->
<!-- |    This document was autogenerated by xacro from ../robot/softleg_cart.urdf.xacro | -->
<!-- |    EDITING THIS FILE BY HAND IS NOT RECOMMENDED                                 | -->
<!-- =================================================================================== -->
<robot name="softleg_cart">
  <!-- INERTIA MATRICES FOR LINKS (wrt frames in urdf inertial) -->
  <material name="SoftLeg/DarkGrey">
    <color rgba="0.3 0.3 0.3 1.0"/>
  </material>
  <material name="SoftLeg/LightGrey">
    <color rgba="0.8 0.8 0.8 1.0"/>
  </material>
  <material name="SoftLeg/Black">
    <color rgba="0 0 0 1.0"/>
  </material>
  <material name="SoftLeg/Silver">
    <color rgba="1.0 1.0 1.0 1.0"/>
  </material>
  <material name="SoftLeg/Grey">
    <color rgba="0.7 0.7 0.7 1.0"/>
  </material>
  <!-- WORLD -->
  <link name="world">
</link>
  <!-- 0) Cart link - fixed to parent. -->
  <joint name="world_softleg_1_fixed_joint" type="fixed">
    <origin rpy="0 0 0" xyz="0 0 0"/>
    <parent link="world"/>
    <child link="softleg_1_cart_link"/>
  </joint>
  <link name="softleg_1_cart_link">
    <inertial>
      <origin xyz="0 0 0"/>
      <mass value="1e-05"/>
      <inertia ixx="1.0000000000000001e-11" ixy="0.0" ixz="0.0" iyy="1.0000000000000001e-11" iyz="0.0" izz="1.0000000000000001e-11"/>
    </inertial>
    <visual>
      <origin rpy="0 0 3.141592653589793" xyz="0 0 0"/>
      <geometry>
        <mesh filename="package://example-robot-data/robots/softleg_description/meshes/visual/cart.dae" scale=" .001 .001 .001"/>
      </geometry>
      <material name="SoftLeg/Grey"/>
    </visual>
    <collision>
      <origin rpy="0 0 0" xyz="0.01 0 0"/>
      <geometry>
        <box size="0.03 0.029 0.008"/>
      </geometry>
    </collision>
  </link>
  <!-- 1) Base link - moves along cart -->
  <joint name="softleg_1_cart_joint" type="prismatic">
    <origin rpy="1.5707963267948966 0.0 1.5707963267948966" xyz="0 -0.01 0"/>
    <axis xyz="0 1 0"/>
    <limit effort="100" lower="0" upper="5" velocity="100"/>
    <dynamics damping="0.0001" friction="0.0001"/>
    <parent link="softleg_1_cart_link"/>
    <child link="softleg_1_base_link"/>
  </joint>
  <link name="softleg_1_base_link">
    <inertial>
      <mass value="0.97245523"/>
      <origin rpy="0 0 0" xyz="0.0356 -0.0011 -0.0078"/>
      <inertia ixx="0.0016984399" ixy="-0.00098390475" ixz="-0.0013053791" iyy="0.020148637999999996" iyz="0.00015383174" izz="0.019764512999999997"/>
    </inertial>
    <visual>
      <origin rpy="0 0 0" xyz="0 0 0"/>
      <geometry>
        <mesh filename="package://example-robot-data/robots/softleg_description/meshes/visual/base.dae" scale=" .001 .001 .001"/>
      </geometry>
      <!-- <material name="SoftLeg/Grey"/> -->
      <material name="darkgray">
        <color rgba=".2 .2 .2 1"/>
      </material>
    </visual>
    <collision>
      <origin rpy="0 0 0" xyz="0.01 0 0"/>
      <geometry>
        <box size="0.03 0.029 0.008"/>
      </geometry>
    </collision>
    <collision>
      <origin rpy="0 0.3 0" xyz="0.0365 0 -0.00375"/>
      <geometry>
        <box size="0.0275 0.025 0.008"/>
      </geometry>
    </collision>
    <collision>
      <origin rpy="0 0.75 0" xyz="0.05525 0 -0.0142"/>
      <geometry>
        <box size="0.021 0.021 0.009"/>
      </geometry>
    </collision>
    <collision>
      <origin rpy="0 1.57 0" xyz="0.0605 0 -0.025"/>
      <geometry>
        <cylinder length="0.0125" radius="0.0075"/>
      </geometry>
    </collision>
  </link>
  <!-- 2) Thigh link - rotates w.r.t base -->
  <joint name="softleg_1_hip_joint" type="revolute">
    <origin rpy="1.5707963267948966 0 0" xyz="0.255 0 0.07"/>
    <axis xyz="0 1 0"/>
    <limit effort="100" lower="-3.141592653589793" upper="3.141592653589793" velocity="100"/>
    <dynamics damping="0.0001" friction="0.0001"/>
    <parent link="softleg_1_base_link"/>
    <child link="softleg_1_thigh_link"/>
  </joint>
  <link name="softleg_1_thigh_link">
    <inertial>
      <mass value="0.43578906"/>
      <origin rpy="0 0 0" xyz="0.0356 -0.0011 -0.0078"/>
      <inertia ixx="0.00075026891" ixy="-0.0010576539999999999" ixz="7.1507533e-08" iyy="0.0045759812" iyz="3.2201256999999996e-07" izz="0.0051059889"/>
    </inertial>
    <visual>
      <origin rpy="0 0 0" xyz="0.073 0 0"/>
      <geometry>
        <mesh filename="package://example-robot-data/robots/softleg_description/meshes/visual/thigh.dae" scale=" .001 .001 .001"/>
      </geometry>
      <material name="SoftLeg/Grey"/>
    </visual>
    <collision>
      <origin rpy="0 0 0" xyz="0.01 0 0"/>
      <geometry>
        <box size="0.03 0.029 0.008"/>
      </geometry>
    </collision>
    <collision>
      <origin rpy="0 0.3 0" xyz="0.0365 0 -0.00375"/>
      <geometry>
        <box size="0.0275 0.025 0.008"/>
      </geometry>
    </collision>
    <collision>
      <origin rpy="0 0.75 0" xyz="0.05525 0 -0.0142"/>
      <geometry>
        <box size="0.021 0.021 0.009"/>
      </geometry>
    </collision>
    <collision>
      <origin rpy="0 1.57 0" xyz="0.0605 0 -0.025"/>
      <geometry>
        <cylinder length="0.0125" radius="0.0075"/>
      </geometry>
    </collision>
  </link>
  <!-- 3) Calf link - rotates w.r.t thigh -->
  <joint name="softleg_1_knee_joint" type="revolute">
    <origin rpy="1.5707963267948966 0 0" xyz="0.175 0.0275 0"/>
    <axis xyz="0 0 -1"/>
    <limit effort="100" lower="-3.141592653589793" upper="3.141592653589793" velocity="100"/>
    <dynamics damping="0.0001" friction="0.0001"/>
    <parent link="softleg_1_thigh_link"/>
    <child link="softleg_1_calf_link"/>
  </joint>
  <link name="softleg_1_calf_link">
    <inertial>
      <mass value="0.076217499"/>
      <origin rpy="0 0 0" xyz="0.0356 -0.0011 -0.0078"/>
      <inertia ixx="6.0006428999999995e-05" ixy="-0.011984835" ixz="3.6890095e-10" iyy="0.00047243319" iyz="1.2686112999999998e-10" izz="0.0005204986699999999"/>
    </inertial>
    <visual>
      <origin rpy="0 0 0" xyz="0 0 0"/>
      <geometry>
        <mesh filename="package://example-robot-data/robots/softleg_description/meshes/visual/calf.dae" scale=" .001 .001 .001"/>
      </geometry>
      <material name="SoftLeg/Grey"/>
    </visual>
    <collision>
      <origin rpy="0 0 0" xyz="0.01 0 0"/>
      <geometry>
        <box size="0.03 0.029 0.008"/>
      </geometry>
    </collision>
    <collision>
      <origin rpy="0 0.3 0" xyz="0.0365 0 -0.00375"/>
      <geometry>
        <box size="0.0275 0.025 0.008"/>
      </geometry>
    </collision>
    <collision>
      <origin rpy="0 0.75 0" xyz="0.05525 0 -0.0142"/>
      <geometry>
        <box size="0.021 0.021 0.009"/>
      </geometry>
    </collision>
    <collision>
      <origin rpy="0 1.57 0" xyz="0.0605 0 -0.025"/>
      <geometry>
        <cylinder length="0.0125" radius="0.0075"/>
      </geometry>
    </collision>
  </link>
  <!-- 4) Contact link - Fixed -->
  <joint name="softleg_1_contact_joint" type="fixed">
    <origin rpy="1.5707963267948966 0 0" xyz="0.185 0 -0.02"/>
    <parent link="softleg_1_calf_link"/>
    <child link="softleg_1_contact_link"/>
  </joint>
  <link name="softleg_1_contact_link">
    <inertial>
      <origin xyz="0 0 0"/>
      <mass value="1e-05"/>
      <inertia ixx="1.0000000000000001e-11" ixy="0.0" ixz="0.0" iyy="1.0000000000000001e-11" iyz="0.0" izz="1.0000000000000001e-11"/>
    </inertial>
  </link>
  <!-- Ros control (For future actuated case) -->
  <!-- <gazebo>
                <plugin name="gazebo_ros_control" filename="libgazebo_ros_control.so">
                    <robotNamespace>${name}</robotNamespace>
                </plugin>
            </gazebo> -->
  <!-- Custom simulation plugin -->
  <gazebo>
    <plugin filename="libsoftleg_gazebo_plugin.so" name="softleg_1_gazebo_sim">
      <robotNamespace>softleg_1</robotNamespace>
    </plugin>
  </gazebo>
  <!-- Provide joint feedback when simulating -->
  <gazebo>
    <plugin filename="libgazebo_ros_joint_state_publisher.so" name="joint_state_publisher">
      <robotNamespace>softleg_1</robotNamespace>
      <jointName>
                                softleg_1_cart_joint, softleg_1_hip_joint,
                                softleg_1_knee_joint
                                </jointName>
      <updateRate>100.0</updateRate>
      <alwaysOn>true</alwaysOn>
    </plugin>
  </gazebo>
  <!-- Leg Links -->
  <gazebo reference="softleg_1_cart_link">
    <gravity>true</gravity>
    <!-- <selfCollide>true</selfCollide> -->
    <material>Gazebo/Grey</material>
    <kp>1e15</kp>
    <kd>1e15</kd>
    <mu1>0.8</mu1>
    <mu2>0.8</mu2>
    <collision>
      <surface>
        <contact>
          <ode>
            <min_depth>0.01</min_depth>
            <max_vel>0.1</max_vel>
          </ode>
        </contact>
      </surface>
    </collision>
  </gazebo>
  <gazebo reference="softleg_1_base_link">
    <gravity>true</gravity>
    <!-- <selfCollide>true</selfCollide> -->
    <material>Gazebo/Grey</material>
    <kp>1e15</kp>
    <kd>1e15</kd>
    <mu1>0.8</mu1>
    <mu2>0.8</mu2>
    <collision>
      <surface>
        <contact>
          <ode>
            <min_depth>0.01</min_depth>
            <max_vel>0.1</max_vel>
          </ode>
        </contact>
      </surface>
    </collision>
  </gazebo>
  <gazebo reference="softleg_1_thigh_link">
    <gravity>true</gravity>
    <!-- <selfCollide>true</selfCollide> -->
    <material>Gazebo/Grey</material>
    <kp>1e15</kp>
    <kd>1e15</kd>
    <mu1>0.8</mu1>
    <mu2>0.8</mu2>
    <collision>
      <surface>
        <contact>
          <ode>
            <min_depth>0.01</min_depth>
            <max_vel>0.1</max_vel>
          </ode>
        </contact>
      </surface>
    </collision>
  </gazebo>
  <gazebo reference="softleg_1_calf_link">
    <gravity>true</gravity>
    <!-- <selfCollide>true</selfCollide> -->
    <material>Gazebo/Grey</material>
    <kp>1e15</kp>
    <kd>1e15</kd>
    <mu1>0.8</mu1>
    <mu2>0.8</mu2>
    <collision>
      <surface>
        <contact>
          <ode>
            <min_depth>0.01</min_depth>
            <max_vel>0.1</max_vel>
          </ode>
        </contact>
      </surface>
    </collision>
  </gazebo>
  <!-- No transmission are needed yet. -->
</robot>

